<?xml version="1.0" ?>
<!-- =================================================================================== -->
<!-- |    This document was autogenerated by xacro from three_fingers_pole.urdf.xacro  | -->
<!-- |    EDITING THIS FILE BY HAND IS NOT RECOMMENDED                                 | -->
<!-- =================================================================================== -->
<!-- =================================================================================== -->
<!-- |    Three fingers manipulator with 6 links, sphere tip (loaded mesh), with pole and target pose        | -->
<!-- =================================================================================== -->
<robot name="3FingersRobot" xmlns:xacro="http://www.ros.org/wiki.xacro">
  <material name="white">
    <color rgba="0.8 0.8 0.8 0"/>
  </material>
  <material name="blue">
    <color rgba="0 0 0.8 0.5"/>
  </material>
  <material name="green">
    <color rgba="0.294 0.84 0.42 1"/>
  </material>
  <material name='yellow'>
    <color rgba="0.63 0.336 0.210 1"/>
  </material>
  <material name="yellow_target">
    <color rgba="1 1 0 0"/>
  </material>
  <material name="red_target">
    <color rgba="1 0 0 0.2"/>
  </material>
  <material name="finger_grey">
    <color rgba="0.384 0.435 .471 1"/>
  </material>
  <material name="finger_light_grey">
    <color rgba="0.592 0.753 0.869 1"/>
  </material>
  <material name="fingertip_blue">
    <color rgba="0.384 0.435 .471 1"/>
  </material>
  <material name="pole_brown">
    <color rgba="1 0.675 0.173 1"/>
  </material>
  <material name="target_pole_brown">
    <color rgba="1 0 0 1."/>
  </material>
  <link name="base">
    <visual>
      <geometry>
        <box size="0.6 0.4 0.02"/>
      </geometry>
      <origin xyz="0 0 0"/>
      <material name="white"/>
    </visual>
    <inertial>
      <mass value="0"/>
      <inertia ixx="1e-3" ixy="0.0" ixz="0.0" iyy="1e-3" iyz="0.0" izz="1e-3"/>
    </inertial>
  </link>
  <link name="1_proximal_link">
    <visual>
      <geometry>
        <cylinder length="0.02" radius="0.011"/>
      </geometry>
      <origin xyz="0 0 0"/>
      <material name="finger_light_grey"/>
    </visual>
    <visual>
      <geometry>
        <box size="0.15 0.02 0.005"/>
      </geometry>
      <origin xyz="0.075 0 0"/>
      <material name="finger_light_grey"/>
    </visual>
    <collision>
      <geometry>
        <box size="0.15 0.02 0.005"/>
      </geometry>
      <origin xyz="0.075 0 0"/>
    </collision>
    <inertial>
      <origin xyz="0.075 0 0"/>
      <mass value="0.1"/>
      <inertia ixx="1.77083333333e-05" ixy="0" ixz="0" iyy="0.000938541666667" iyz="0" izz="0.000954166666667"/>
    </inertial>
  </link>
  <joint name="1_base_joint" type="revolute">
    <parent link="base"/>
    <child link="1_proximal_link"/>
    <origin rpy="0 0 3.1415/2.0" xyz="0 0.2 0.02"/>
    <axis xyz="0 0 1"/>
    <limit effort="10000.0" lower="-3.14" upper="3.14" velocity="5"/>
    <dynamics damping="0" friction="0"/>
  </joint>
  <link name="1_distal_link">
    <visual>
      <geometry>
        <box size="0.09 0.02 0.005"/>
      </geometry>
      <origin xyz="0.045 0 0"/>
      <material name="finger_grey"/>
    </visual>
    <visual name="1_fingertip">
      <geometry>
        <mesh filename="./cylinder.dae" scale="0.01 0.01 0.01"/>
      </geometry>
      <origin xyz="0.09 0 0"/>
      <material name="fingertip_blue"/>
    </visual>
    <collision>
      <geometry>
        <mesh filename="./cylinder.dae" scale="0.01 0.01 0.01"/>
      </geometry>
      <origin xyz="0.09 0 0"/>
    </collision>
    <collision>
      <geometry>
        <box size="0.09 0.02 0.005"/>
      </geometry>
      <origin xyz="0.045 0 0"/>
    </collision>
    <inertial>
      <origin xyz="0.05 0 0"/>
      <mass value="0.1"/>
      <inertia ixx="3.33333333333e-05" ixy="0" ixz="0" iyy="0.000433333333333" iyz="0" izz="0.000433333333333"/>
    </inertial>
  </link>
  <joint name="1_central_joint" type="revolute">
    <parent link="1_proximal_link"/>
    <child link="1_distal_link"/>
    <origin xyz="0.15 0 0"/>
    <axis xyz="0 0 1"/>
    <limit effort="10000.0" lower="-3.14" upper="3.14" velocity="5"/>
    <dynamics damping="0" friction="0"/>
  </joint>
  <link name="2_proximal_link">
    <visual>
      <geometry>
        <cylinder length="0.02" radius="0.011"/>
      </geometry>
      <origin xyz="0 0 0"/>
      <material name="finger_light_grey"/>
    </visual>
    <visual>
      <geometry>
        <box size="0.15 0.02 0.005"/>
      </geometry>
      <origin xyz="0.075 0 0"/>
      <material name="finger_light_grey"/>
    </visual>
    <collision>
      <geometry>
        <box size="0.15 0.02 0.005"/>
      </geometry>
      <origin xyz="0.075 0 0"/>
    </collision>
    <inertial>
      <origin xyz="0.075 0 0"/>
      <mass value="0.1"/>
      <inertia ixx="1.77083333333e-05" ixy="0" ixz="0" iyy="0.000938541666667" iyz="0" izz="0.000954166666667"/>
    </inertial>
  </link>
  <joint name="2_base_joint" type="revolute">
    <parent link="base"/>
    <child link="2_proximal_link"/>
    <origin rpy="0 0 0" xyz="-0.1 -0.2 0.02"/>
    <axis xyz="0 0 1"/>
    <limit effort="10000.0" lower="-3.14" upper="3.14" velocity="5"/>
    <dynamics damping="0" friction="0"/>
  </joint>
  <link name="2_distal_link">
    <visual>
      <geometry>
        <box size="0.09 0.02 0.005"/>
      </geometry>
      <origin xyz="0.045 0 0"/>
      <material name="finger_grey"/>
    </visual>
    <visual name="2_fingertip">
      <geometry>
        <mesh filename="./cylinder.dae" scale="0.01 0.01 0.01"/>
      </geometry>
      <origin xyz="0.09 0 0"/>
      <material name="fingertip_blue"/>
    </visual>
    <collision>
      <geometry>
        <mesh filename="./cylinder.dae" scale="0.01 0.01 0.01"/>
      </geometry>
      <origin xyz="0.09 0 0"/>
    </collision>
    <collision>
      <geometry>
        <box size="0.09 0.02 0.005"/>
      </geometry>
      <origin xyz="0.045 0 0"/>
    </collision>
    <inertial>
      <origin xyz="0.05 0 0"/>
      <mass value="0.1"/>
      <inertia ixx="3.33333333333e-05" ixy="0" ixz="0" iyy="0.000433333333333" iyz="0" izz="0.000433333333333"/>
    </inertial>
  </link>
  <joint name="2_central_joint" type="revolute">
    <parent link="2_proximal_link"/>
    <child link="2_distal_link"/>
    <origin xyz="0.15 0 0"/>
    <axis xyz="0 0 1"/>
    <limit effort="10000.0" lower="-3.14" upper="3.14" velocity="5"/>
    <dynamics damping="0" friction="0"/>
  </joint>
  <link name="3_proximal_link">
    <visual>
      <geometry>
        <cylinder length="0.02" radius="0.011"/>
      </geometry>
      <origin xyz="0 0 0"/>
      <material name="finger_light_grey"/>
    </visual>
    <visual>
      <geometry>
        <box size="0.15 0.02 0.005"/>
      </geometry>
      <origin xyz="0.075 0 0"/>
      <material name="finger_light_grey"/>
    </visual>
    <collision>
      <geometry>
        <box size="0.15 0.02 0.005"/>
      </geometry>
      <origin xyz="0.075 0 0"/>
    </collision>
    <inertial>
      <origin xyz="0.075 0 0"/>
      <mass value="0.1"/>
      <inertia ixx="1.77083333333e-05" ixy="0" ixz="0" iyy="0.000938541666667" iyz="0" izz="0.000954166666667"/>
    </inertial>
  </link>
  <joint name="3_base_joint" type="revolute">
    <parent link="base"/>
    <child link="3_proximal_link"/>
    <origin rpy="0 0 0" xyz="0.1 -0.2 0.02"/>
    <axis xyz="0 0 1"/>
    <limit effort="10000.0" lower="-3.14" upper="3.14" velocity="5"/>
    <dynamics damping="0" friction="0"/>
  </joint>
  <link name="3_distal_link">
    <visual>
      <geometry>
        <box size="0.09 0.02 0.005"/>
      </geometry>
      <origin xyz="0.045 0 0"/>
      <material name="finger_grey"/>
    </visual>
    <visual name="3_fingertip">
      <geometry>
        <mesh filename="./cylinder.dae" scale="0.01 0.01 0.01"/>
      </geometry>
      <origin xyz="0.09 0 0"/>
      <material name="fingertip_blue"/>
    </visual>
    <collision>
      <geometry>
        <mesh filename="./cylinder.dae" scale="0.01 0.01 0.01"/>
      </geometry>
      <origin xyz="0.09 0 0"/>
    </collision>
    <collision>
      <geometry>
        <box size="0.09 0.02 0.005"/>
      </geometry>
      <origin xyz="0.045 0 0"/>
    </collision>
    <inertial>
      <origin xyz="0.05 0 0"/>
      <mass value="0.1"/>
      <inertia ixx="3.33333333333e-05" ixy="0" ixz="0" iyy="0.000433333333333" iyz="0" izz="0.000433333333333"/>
    </inertial>
  </link>
  <joint name="3_central_joint" type="revolute">
    <parent link="3_proximal_link"/>
    <child link="3_distal_link"/>
    <origin xyz="0.15 0 0"/>
    <axis xyz="0 0 1"/>
    <limit effort="10000.0" lower="-3.14" upper="3.14" velocity="5"/>
    <dynamics damping="0" friction="0"/>
  </joint>
  <!-- dummy link for 2D constraints -->
  <link name="object_dummy_link_1">
    <inertial>
      <mass value="0"/>
      <inertia ixx="1e-3" ixy="0.0" ixz="0.0" iyy="1e-3" iyz="0.0" izz="1e-3"/>
    </inertial>
  </link>
  <link name="object_dummy_link_2">
    <inertial>
      <mass value="0"/>
      <inertia ixx="1e-3" ixy="0.0" ixz="0.0" iyy="1e-3" iyz="0.0" izz="1e-3"/>
    </inertial>
  </link>
  
  <link name="object_pole">
    <visual>
      <geometry>
        <mesh filename="./pole.dae" scale="0.05 0.05 0.05"/>
      </geometry>
      <origin xyz="0 0 0"/>
      <material name='pole_brown'/>
    </visual>
    <collision>
      <geometry>
        <mesh filename="./pole.dae" scale="0.05 0.05 0.05"/>
      </geometry>
      <origin xyz="0 0 0"/>
    </collision>
    <inertial>
      <origin xyz="0 0 0"/>
      <mass value="0.01"/>
      <inertia ixx="1.77083333333e-05" ixy="0" ixz="0" iyy="0.0104177083333" iyz="0" izz="0.0104333333333"/>
    </inertial>
  </link>
  <joint name="object_base_pole_x" type="prismatic">
    <parent link="base"/>
    <child link="object_dummy_link_1"/>
    <origin xyz="0 0 0"/>
    <axis xyz="1 0 0"/>
    <dynamics damping="0" friction="0"/>
    <limit effort="10000.0" lower="-100" upper="100" velocity="5"/>
  </joint>
  <joint name="object_base_pole_y" type="prismatic">
    <parent link="object_dummy_link_1"/>
    <child link="object_dummy_link_2"/>
    <origin xyz="0 0 0"/>
    <axis xyz="0 1 0"/>
    <limit effort="10000.0" lower="-100" upper="100" velocity="5"/>
    <dynamics damping="0" friction="0"/>
  </joint>
  <joint name="object_base_pole_theta" type="revolute">
    <parent link="object_dummy_link_2"/>
    <child link="object_pole"/>
    <origin xyz="0 0 0.02"/>
    <axis xyz="0 0 1"/>
    <limit effort="10000.0" lower="-3.14" upper="3.14" velocity="5"/>
    <dynamics damping="0" friction="0"/>
  </joint>
  <link name="target_dummy_link_1">
    <inertial>
      <mass value="0"/>
      <inertia ixx="1e-3" ixy="0.0" ixz="0.0" iyy="1e-3" iyz="0.0" izz="1e-3"/>
    </inertial>
  </link>
  <link name="target_dummy_link_2">
    <inertial>
      <mass value="0"/>
      <inertia ixx="1e-3" ixy="0.0" ixz="0.0" iyy="1e-3" iyz="0.0" izz="1e-3"/>
    </inertial>
  </link>
  <link name="target_pole">
    <visual>
      <geometry>
        <box size="0.5 0.005 0.005"/>
      </geometry>
      <origin xyz="0 0 0"/>
      <material name="target_pole_brown"/>
    </visual>
    <inertial>
      <origin xyz="0 0 0"/>
      <mass value="0."/>
      <inertia ixx="1.77083333333e-05" ixy="0" ixz="0" iyy="0.0104177083333" iyz="0" izz="0.0104333333333"/>
    </inertial>
  </link>
  <joint name="target_base_pole_x" type="prismatic">
    <parent link="base"/>
    <child link="target_dummy_link_1"/>
    <origin xyz="0 0 0"/>
    <axis xyz="1 0 0"/>
    <dynamics damping="0" friction="0"/>
    <limit effort="10000.0" lower="-100" upper="100" velocity="5"/>
  </joint>
  <joint name="target_base_pole_y" type="prismatic">
    <parent link="target_dummy_link_1"/>
    <child link="target_dummy_link_2"/>
    <origin xyz="0 0 0"/>
    <axis xyz="0 1 0"/>
    <limit effort="10000.0" lower="-100" upper="100" velocity="5"/>
    <dynamics damping="0" friction="0"/>
  </joint>
  <joint name="target_base_pole_theta" type="revolute">
    <parent link="target_dummy_link_2"/>
    <child link="target_pole"/>
    <origin xyz="0 0 0.02"/>
    <axis xyz="0 0 1"/>
    <limit effort="10000.0" lower="-3.14" upper="3.14" velocity="5"/>
    <dynamics damping="0" friction="0"/>
  </joint>

  <link name="target_local_dummy_link_1">
    <inertial>
      <mass value="0"/>
      <inertia ixx="1e-3" ixy="0.0" ixz="0.0" iyy="1e-3" iyz="0.0" izz="1e-3"/>
    </inertial>
  </link>
  <link name="target_local_dummy_link_2">
    <inertial>
      <mass value="0"/>
      <inertia ixx="1e-3" ixy="0.0" ixz="0.0" iyy="1e-3" iyz="0.0" izz="1e-3"/>
    </inertial>
  </link>
  <link name="target_local_pole">
    <visual>
      <geometry>
        <box size="0.5 0.02 0.005"/>
      </geometry>
      <origin xyz="0 0 0"/>
      <material name="red_target"/>
    </visual>
    <inertial>
      <origin xyz="0 0 0"/>
      <mass value="0."/>
      <inertia ixx="1.77083333333e-05" ixy="0" ixz="0" iyy="0.0104177083333" iyz="0" izz="0.0104333333333"/>
    </inertial>
  </link>
  <link name="target_contact_local_point_f1">
    <visual>
        <geometry>
            <sphere radius="0.01"/>
        </geometry>
        <material name="blue"/>
    </visual>
    <inertial>
      <mass value="0"/>
      <inertia ixx="1e-3" ixy="0.0" ixz="0.0" iyy="1e-3" iyz="0.0" izz="1e-3"/>
    </inertial>
  </link>
  <link name="target_contact_local_point_f2">
    <visual>
        <geometry>
            <sphere radius="0.01"/>
        </geometry>
        <material name="blue"/>
    </visual>
    <inertial>
      <mass value="0"/>
      <inertia ixx="1e-3" ixy="0.0" ixz="0.0" iyy="1e-3" iyz="0.0" izz="1e-3"/>
    </inertial>
  </link>
  <link name="target_contact_local_point_f3">
    <visual>
        <geometry>
            <sphere radius="0.01"/>
        </geometry>
        <material name="blue"/>
    </visual>
    <inertial>
      <mass value="0"/>
      <inertia ixx="1e-3" ixy="0.0" ixz="0.0" iyy="1e-3" iyz="0.0" izz="1e-3"/>
    </inertial>
  </link>

  <joint name="target_local_base_pole_x" type="prismatic">
    <parent link="base"/>
    <child link="target_local_dummy_link_1"/>
    <origin xyz="0 0 0"/>
    <axis xyz="1 0 0"/>
    <dynamics damping="0" friction="0"/>
    <limit effort="10000.0" lower="-100" upper="100" velocity="5"/>
  </joint>
  <joint name="target_local_base_pole_y" type="prismatic">
    <parent link="target_local_dummy_link_1"/>
    <child link="target_local_dummy_link_2"/>
    <origin xyz="0 0 0"/>
    <axis xyz="0 1 0"/>
    <limit effort="10000.0" lower="-100" upper="100" velocity="5"/>
    <dynamics damping="0" friction="0"/>
  </joint>
  <joint name="target_local_base_pole_theta" type="revolute">
    <parent link="target_local_dummy_link_2"/>
    <child link="target_local_pole"/>
    <origin xyz="0 0 0.02"/>
    <axis xyz="0 0 1"/>
    <limit effort="10000.0" lower="-3.14" upper="3.14" velocity="5"/>
    <dynamics damping="0" friction="0"/>
  </joint>

  <joint name="target_contact_local_point_f1_joint" type="prismatic">
    <parent link="target_local_pole"/>
    <child link="target_contact_local_point_f1"/>
    <origin xyz="0 0 0"/>
    <axis xyz="1 0 0"/>
    <dynamics damping="0" friction="0"/>
    <limit effort="10000.0" lower="-100" upper="100" velocity="5"/>
  </joint>
  <joint name="target_contact_local_point_f2_joint" type="prismatic">
    <parent link="target_local_pole"/>
    <child link="target_contact_local_point_f2"/>
    <origin xyz="0 0 0"/>
    <axis xyz="1 0 0"/>
    <dynamics damping="0" friction="0"/>
    <limit effort="10000.0" lower="-100" upper="100" velocity="5"/>
  </joint>
  <joint name="target_contact_local_point_f3_joint" type="prismatic">
    <parent link="target_local_pole"/>
    <child link="target_contact_local_point_f3"/>
    <origin xyz="0 0 0"/>
    <axis xyz="1 0 0"/>
    <dynamics damping="0" friction="0"/>
    <limit effort="10000.0" lower="-100" upper="100" velocity="5"/>
  </joint>
</robot>

